<?xml version='1.0'?>

<robot name="mogi_bot" xmlns:xacro="http://www.ros.org/wiki/xacro">

  <!-- STEP 3 - Gazebo plugin -->
  <xacro:include filename="$(find bme_gazebo_basics)/urdf/mogi_bot.gazebo" />

  <!-- STEP 4 - RViz colors -->
  <xacro:include filename="$(find bme_gazebo_basics)/urdf/materials.xacro" />

  <!-- STEP 1 - Robot chassis -->
  <link name="base_footprint"></link>

  <joint name="base_footprint_joint" type="fixed">
    <origin xyz="0 0 0" rpy="0 0 0" />
    <parent link="base_footprint"/>
    <child link="base_link" />
  </joint>

  <link name='base_link'>
    <pose>0 0 0.1 0 0 0</pose>

    <inertial>
      <mass value="15.0"/>
      <origin xyz="0.0 0 0" rpy=" 0 0 0"/>
      <inertia
          ixx="0.0625" ixy="0" ixz="0"
          iyy="0.2125" iyz="0"
          izz="0.25"
      />
    </inertial>

    <collision name='collision'>
      <origin xyz="0 0 0" rpy=" 0 0 0"/> 
      <geometry>
        <box size=".4 .2 .1"/>
      </geometry>
    </collision>

    <visual name='base_link_visual'>
      <origin xyz="0 0 0" rpy=" 0 0 0"/>
      <geometry>
        <box size=".4 .2 .1"/>
        <!-- <mesh filename = "package://bme_gazebo_basics/meshes/mogi_bot.dae"/> -->
      </geometry>
      <material name="orange"/>
    </visual>

    <collision name='rear_caster_collision'>
      <origin xyz="-0.15 0 -0.05" rpy=" 0 0 0"/>
      <geometry>
        <sphere radius="0.0499"/>
      </geometry>
    </collision>

    <visual name='rear_caster_visual'>
      <origin xyz="-0.15 0 -0.05" rpy=" 0 0 0"/>
      <geometry>
        <sphere radius="0.05"/>
      </geometry>
    </visual>

    <collision name='front_caster_collision'>
      <origin xyz="0.15 0 -0.05" rpy=" 0 0 0"/>
      <geometry>
        <sphere radius="0.0499"/>
      </geometry>
    </collision>

    <visual name='front_caster_visual'>
      <origin xyz="0.15 0 -0.05" rpy=" 0 0 0"/>
      <geometry>
        <sphere radius="0.05"/>
      </geometry>
    </visual>

  </link>

  <!-- STEP 2 - Wheels -->
  <joint type="continuous" name="left_wheel_joint">
    <origin xyz="0 0.15 0" rpy="0 0 0"/>
    <child link="left_wheel"/>
    <parent link="base_link"/>
    <axis xyz="0 1 0" rpy="0 0 0"/>
    <limit effort="100" velocity="10"/>
    <dynamics damping="1.0" friction="1.0"/>
  </joint>

  <link name='left_wheel'>
    <inertial>
      <mass value="5.0"/>
      <origin xyz="0 0 0" rpy="0 1.5707 1.5707"/>
      <inertia
          ixx="0.014" ixy="0" ixz="0"
          iyy="0.014" iyz="0"
          izz="0.025"
      />
    </inertial>

    <collision name='collision'>
      <origin xyz="0 0 0" rpy="0 1.5707 1.5707"/> 
      <geometry>
        <cylinder radius=".1" length=".05"/>
      </geometry>
    </collision>

    <visual name='left_wheel_visual'>
      <origin xyz="0 0 0" rpy="0 1.5707 1.5707"/>
      <geometry>
        <cylinder radius=".1" length=".05"/>
        <!-- <mesh filename = "package://bme_gazebo_basics/meshes/wheel.dae"/> -->
      </geometry>
      <material name="green"/>
    </visual>
  </link>

  <joint type="continuous" name="right_wheel_joint">
    <origin xyz="0 -0.15 0" rpy="0 0 0"/>
    <child link="right_wheel"/>
    <parent link="base_link"/>
    <axis xyz="0 1 0" rpy="0 0 0"/>
    <limit effort="100" velocity="10"/>
    <dynamics damping="1.0" friction="1.0"/>
  </joint>

  <link name='right_wheel'>
    <inertial>
      <mass value="5.0"/>
      <origin xyz="0 0 0" rpy="0 1.5707 1.5707"/>
      <inertia
          ixx="0.014" ixy="0" ixz="0"
          iyy="0.014" iyz="0"
          izz="0.025"
      />
    </inertial>

    <collision name='collision'>
      <origin xyz="0 0 0" rpy="0 1.5707 1.5707"/> 
      <geometry>
        <cylinder radius=".1" length=".05"/>
      </geometry>
    </collision>

    <visual name='right_wheel_visual'>
      <origin xyz="0 0 0" rpy="0 1.5707 1.5707"/>
      <geometry>
        <cylinder radius=".1" length=".05"/>
        <!-- <mesh filename = "package://bme_gazebo_basics/meshes/wheel.dae"/> -->
      </geometry>
      <material name="green"/>
    </visual>
  </link>

  <!-- STEP 4 - Gazebo frictions and colors -->
  <gazebo reference="left_wheel">
    <mu1>0.2</mu1>
    <mu2>0.2</mu2>
    <kp>1000000.0</kp>
    <kd>100.0</kd>
    <minDepth>0.0001</minDepth>
    <maxVel>1.0</maxVel>
    <material>Gazebo/Green</material>
  </gazebo>

  <gazebo reference="right_wheel">
    <mu1>0.2</mu1>
    <mu2>0.2</mu2>
    <kp>1000000.0</kp>
    <kd>100.0</kd>
    <minDepth>0.0001</minDepth>
    <maxVel>1.0</maxVel>
    <material>Gazebo/Green</material>
  </gazebo>

  <gazebo reference="base_link">
    <mu1>0.000002</mu1>
    <mu2>0.000002</mu2>
    <material>Gazebo/Orange</material>
  </gazebo>

</robot>