<?xml version='1.0'?>

<robot name="mogi_bot" xmlns:xacro="http://www.ros.org/wiki/xacro" xmlns:gz="http://gazebosim.org/schema">

  <!-- STEP 5 - Gazebo plugin -->
  <xacro:include filename="$(find bme_gazebo_basics)/urdf/mogi_bot_mecanum.gazebo" />

  <!-- STEP 4 - RViz colors -->
  <xacro:include filename="$(find bme_gazebo_basics)/urdf/materials.xacro" />

  <!-- STEP 1 - Robot footprint -->
  <link name="base_footprint"></link>

  <!-- STEP 2 - Robot chassis = base_link -->
  <joint name="base_footprint_joint" type="fixed">
    <origin xyz="0 0 0" rpy="0 0 0" />
    <parent link="base_footprint"/>
    <child link="base_link" />
  </joint>

  <link name='base_link'>
    <pose>0 0 0.1 0 0 0</pose>

    <inertial>
      <mass value="15.0"/>
      <origin xyz="0.0 0 0" rpy=" 0 0 0"/>
      <inertia
          ixx="0.0625" ixy="0" ixz="0"
          iyy="0.2125" iyz="0"
          izz="0.25"
      />
    </inertial>

    <collision>
      <origin xyz="0 0 0" rpy=" 0 0 0"/> 
      <geometry>
        <box size=".4 .2 .1"/>
      </geometry>
    </collision>

    <visual name='base_link_visual'>
      <origin xyz="0 0 0" rpy=" 0 0 0"/>
      <geometry>
        <!-- <box size=".4 .2 .1"/> -->
        <mesh filename = "package://bme_gazebo_basics/meshes/mogi_bot.dae"/>
      </geometry>
      <!-- <material name="orange"/> -->
    </visual>

  </link>

  <!-- STEP 3 - Wheels -->
  <joint type="continuous" name="front_left_wheel_joint">
    <origin xyz="0.15 0.15 0" rpy="-1.5707 0 0"/>
    <child link="front_left_wheel"/>
    <parent link="base_link"/>
    <axis xyz="0 0 1" rpy="0 0 0"/>
    <limit effort="10000" velocity="10"/>
    <dynamics damping="1.0" friction="1.0"/>
  </joint>

  <link name='front_left_wheel'>
    <inertial>
      <mass value="2.0"/>
      <origin xyz="0 0 0" rpy="0 0 0"/>
      <inertia
          ixx="0.145833" ixy="0" ixz="0"
          iyy="0.145833" iyz="0"
          izz="0.125"
      />
    </inertial>

    <collision>
      <geometry>
        <sphere radius=".1"/>
      </geometry>
    </collision>

    <visual name='front_left_wheel_visual'>
      <origin xyz="0 0 0" rpy="1.5707 0 0"/>
      <geometry>
        <!-- <sphere radius=".1"/> -->
        <mesh filename="package://bme_gazebo_basics/meshes/mecanum_wheel_left.STL" scale="0.002 .002 0.002"/>
      </geometry>
      <material name="green"/>
    </visual>
  </link>

  <joint type="continuous" name="rear_left_wheel_joint">
    <origin xyz="-0.15 0.15 0" rpy="-1.5707 0 0"/>
    <child link="rear_left_wheel"/>
    <parent link="base_link"/>
    <axis xyz="0 0 1" rpy="0 0 0"/>
    <limit effort="10000" velocity="10"/>
    <dynamics damping="1.0" friction="1.0"/>
  </joint>

  <link name='rear_left_wheel'>
    <inertial>
      <mass value="2.0"/>
      <origin xyz="0 0 0" rpy="0 0 0"/>
      <inertia
          ixx="0.145833" ixy="0" ixz="0"
          iyy="0.145833" iyz="0"
          izz="0.125"
      />
    </inertial>

    <collision>
      <geometry>
        <sphere radius=".1"/>
      </geometry>
    </collision>

    <visual name='rear_left_wheel_visual'>
      <origin xyz="0 0 0" rpy="1.5707 0 0"/>
      <geometry>
        <!-- <sphere radius=".1"/> -->
        <mesh filename="package://bme_gazebo_basics/meshes/mecanum_wheel_right.STL" scale="0.002 .002 0.002"/>
      </geometry>
      <material name="green"/>
    </visual>
  </link>

  <joint type="continuous" name="front_right_wheel_joint">
    <origin xyz="0.15 -0.15 0" rpy="-1.5707 0 0"/>
    <child link="front_right_wheel"/>
    <parent link="base_link"/>
    <axis xyz="0 0 1" rpy="0 0 0"/>
    <limit effort="10000" velocity="10"/>
    <dynamics damping="1.0" friction="1.0"/>
  </joint>

  <link name='front_right_wheel'>
    <inertial>
      <mass value="2.0"/>
      <origin xyz="0 0 0" rpy="0 0 0"/>
      <inertia
          ixx="0.145833" ixy="0" ixz="0"
          iyy="0.145833" iyz="0"
          izz="0.125"
      />
    </inertial>

    <collision>
      <geometry>
        <sphere radius=".1"/>
      </geometry>
    </collision>

    <visual name='front_right_wheel_visual'>
      <origin xyz="0 0 0" rpy="1.5707 0 0"/>
      <geometry>
        <!-- <sphere radius=".1"/> -->
        <mesh filename="package://bme_gazebo_basics/meshes/mecanum_wheel_right.STL" scale="0.002 .002 0.002"/>
      </geometry>
      <material name="green"/>
    </visual>
  </link>

  <joint type="continuous" name="rear_right_wheel_joint">
    <origin xyz="-0.15 -0.15 0" rpy="-1.5707 0 0"/>
    <child link="rear_right_wheel"/>
    <parent link="base_link"/>
    <axis xyz="0 0 1" rpy="0 0 0"/>
    <limit effort="10000" velocity="10"/>
    <dynamics damping="1.0" friction="1.0"/>
  </joint>

  <link name='rear_right_wheel'>
    <inertial>
      <mass value="2.0"/>
      <origin xyz="0 0 0" rpy="0 0 0"/>
      <inertia
          ixx="0.145833" ixy="0" ixz="0"
          iyy="0.145833" iyz="0"
          izz="0.125"
      />
    </inertial>

    <collision>
      <geometry>
        <sphere radius=".1"/>
      </geometry>
    </collision>

    <visual name='rear_right_wheel_visual'>
      <origin xyz="0 0 0" rpy="1.5707 0 0"/>
      <geometry>
        <!-- <sphere radius=".1"/> -->
        <mesh filename="package://bme_gazebo_basics/meshes/mecanum_wheel_left.STL" scale="0.002 .002 0.002"/>
      </geometry>
      <material name="green"/>
    </visual>
  </link>

  <!-- STEP 6 - Gazebo frictions and colors -->
  <gazebo reference='front_left_wheel'>
    <collision>
      <surface>
        <friction>
          <ode>
            <mu>1.5</mu>
            <mu2>0.0</mu2>
            <fdir1 gz:expressed_in="base_footprint">1 -1 0</fdir1>
          </ode>
        </friction>
      </surface>
    </collision>
  </gazebo>

  <gazebo reference='rear_left_wheel'>
    <collision>
      <surface>
        <friction>
          <ode>
            <mu>1.5</mu>
            <mu2>0.0</mu2>
            <fdir1 gz:expressed_in="base_footprint">1 1 0</fdir1>
          </ode>
        </friction>
      </surface>
    </collision>
  </gazebo>

  <gazebo reference='front_right_wheel'>
    <collision>
      <surface>
        <friction>
          <ode>
            <mu>1.5</mu>
            <mu2>0.0</mu2>
            <fdir1 gz:expressed_in="base_footprint">1 1 0</fdir1>
          </ode>
        </friction>
      </surface>
    </collision>
  </gazebo>

  <gazebo reference='rear_right_wheel'>
    <collision>
      <surface>
        <friction>
          <ode>
            <mu>1.5</mu>
            <mu2>0.0</mu2>
            <fdir1 gz:expressed_in="base_footprint">1 -1 0</fdir1>
          </ode>
        </friction>
      </surface>
    </collision>
  </gazebo>

  <gazebo reference="base_link">
    <mu1>0.000002</mu1>
    <mu2>0.000002</mu2>
    <!-- <material>Gazebo/Red</material> -->
  </gazebo>

</robot>